INFO:werkzeug:[31m[1mWARNING: This is a development server. Do not use it in a production deployment. Use a production WSGI server instead.[0m
 * Running on http://127.0.0.1:5000
INFO:werkzeug:[33mPress CTRL+C to quit[0m
INFO:werkzeug:127.0.0.1 - - [15/Apr/2024 11:34:40] "GET / HTTP/1.1" 200 -
DEBUG:urllib3.connectionpool:Starting new HTTPS connection (1): zoom.us:443
DEBUG:urllib3.connectionpool:https://zoom.us:443 "POST /oauth/token HTTP/1.1" 400 None
ERROR:zoomOAUTH:Exception on /getAccess [GET]
Traceback (most recent call last):
  File "/home/austinmedina/DataLabMetrtics/Metrics/lib/python3.10/site-packages/flask/app.py", line 1463, in wsgi_app
    response = self.full_dispatch_request()
  File "/home/austinmedina/DataLabMetrtics/Metrics/lib/python3.10/site-packages/flask/app.py", line 872, in full_dispatch_request
    rv = self.handle_user_exception(e)
  File "/home/austinmedina/DataLabMetrtics/Metrics/lib/python3.10/site-packages/flask/app.py", line 870, in full_dispatch_request
    rv = self.dispatch_request()
  File "/home/austinmedina/DataLabMetrtics/Metrics/lib/python3.10/site-packages/flask/app.py", line 855, in dispatch_request
    return self.ensure_sync(self.view_functions[rule.endpoint])(**view_args)  # type: ignore[no-any-return]
  File "/home/austinmedina/DataLabMetrtics/zoomApp/zoomOAUTH.py", line 54, in getAccess
    app.logger(re)
TypeError: 'Logger' object is not callable
INFO:werkzeug:127.0.0.1 - - [15/Apr/2024 11:34:44] "[35m[1mGET /getAccess?code=bMK7IvBjR89xBrP7EAQTyWHM17KJ4B-kg HTTP/1.1[0m" 500 -
INFO:werkzeug:[31m[1mWARNING: This is a development server. Do not use it in a production deployment. Use a production WSGI server instead.[0m
 * Running on http://127.0.0.1:5000
INFO:werkzeug:[33mPress CTRL+C to quit[0m
DEBUG:urllib3.connectionpool:Starting new HTTPS connection (1): zoom.us:443
DEBUG:urllib3.connectionpool:https://zoom.us:443 "POST /oauth/token HTTP/1.1" 400 None
INFO:zoomOAUTH:{'reason': 'Invalid client_id or client_secret', 'error': 'invalid_client'}
ERROR:zoomOAUTH:Exception on /getAccess [GET]
Traceback (most recent call last):
  File "/home/austinmedina/DataLabMetrtics/Metrics/lib/python3.10/site-packages/flask/app.py", line 1463, in wsgi_app
    response = self.full_dispatch_request()
  File "/home/austinmedina/DataLabMetrtics/Metrics/lib/python3.10/site-packages/flask/app.py", line 872, in full_dispatch_request
    rv = self.handle_user_exception(e)
  File "/home/austinmedina/DataLabMetrtics/Metrics/lib/python3.10/site-packages/flask/app.py", line 870, in full_dispatch_request
    rv = self.dispatch_request()
  File "/home/austinmedina/DataLabMetrtics/Metrics/lib/python3.10/site-packages/flask/app.py", line 855, in dispatch_request
    return self.ensure_sync(self.view_functions[rule.endpoint])(**view_args)  # type: ignore[no-any-return]
  File "/home/austinmedina/DataLabMetrtics/zoomApp/zoomOAUTH.py", line 55, in getAccess
    session['refresh_token'] = re['refresh_token']
KeyError: 'refresh_token'
INFO:werkzeug:127.0.0.1 - - [15/Apr/2024 11:35:46] "[35m[1mGET /getAccess?code=bMK7IvBjR89xBrP7EAQTyWHM17KJ4B-kg HTTP/1.1[0m" 500 -
INFO:werkzeug:[31m[1mWARNING: This is a development server. Do not use it in a production deployment. Use a production WSGI server instead.[0m
 * Running on http://127.0.0.1:5000
INFO:werkzeug:[33mPress CTRL+C to quit[0m
DEBUG:urllib3.connectionpool:Starting new HTTPS connection (1): zoom.us:443
DEBUG:urllib3.connectionpool:https://zoom.us:443 "POST /oauth/token HTTP/1.1" 400 None
INFO:zoomOAUTH:{'reason': 'Invalid authorization code', 'error': 'invalid_grant'}
ERROR:zoomOAUTH:Exception on /getAccess [GET]
Traceback (most recent call last):
  File "/home/austinmedina/DataLabMetrtics/Metrics/lib/python3.10/site-packages/flask/app.py", line 1463, in wsgi_app
    response = self.full_dispatch_request()
  File "/home/austinmedina/DataLabMetrtics/Metrics/lib/python3.10/site-packages/flask/app.py", line 872, in full_dispatch_request
    rv = self.handle_user_exception(e)
  File "/home/austinmedina/DataLabMetrtics/Metrics/lib/python3.10/site-packages/flask/app.py", line 870, in full_dispatch_request
    rv = self.dispatch_request()
  File "/home/austinmedina/DataLabMetrtics/Metrics/lib/python3.10/site-packages/flask/app.py", line 855, in dispatch_request
    return self.ensure_sync(self.view_functions[rule.endpoint])(**view_args)  # type: ignore[no-any-return]
  File "/home/austinmedina/DataLabMetrtics/zoomApp/zoomOAUTH.py", line 55, in getAccess
    session['refresh_token'] = re['refresh_token']
KeyError: 'refresh_token'
INFO:werkzeug:127.0.0.1 - - [15/Apr/2024 11:40:20] "[35m[1mGET /getAccess?code=bMK7IvBjR89xBrP7EAQTyWHM17KJ4B-kg HTTP/1.1[0m" 500 -
INFO:werkzeug:127.0.0.1 - - [15/Apr/2024 11:42:28] "GET / HTTP/1.1" 200 -
DEBUG:urllib3.connectionpool:Starting new HTTPS connection (1): zoom.us:443
DEBUG:urllib3.connectionpool:https://zoom.us:443 "POST /oauth/token HTTP/1.1" 200 None
INFO:zoomOAUTH:{'access_token': 'eyJzdiI6IjAwMDAwMSIsImFsZyI6IkhTNTEyIiwidiI6IjIuMCIsImtpZCI6IjVkOTM1NGIyLWY2ZDgtNGZiZi04NzU2LTRhNjMxYzhkNjI4ZSJ9.eyJ2ZXIiOjksImF1aWQiOiI2NmQ1MzMxODA5NzZhNjQ5MGY5YzQzODdlNjc2YTQxNSIsImNvZGUiOiJSc1ZqS3ZoZTNpbGI5VXptOWFGU1N1NWNXYnBYVjhPZXciLCJpc3MiOiJ6bTpjaWQ6UWhoWmZIYXdSbE4xdEtqNkJ2S1BBIiwiZ25vIjowLCJ0eXBlIjowLCJ0aWQiOjAsImF1ZCI6Imh0dHBzOi8vb2F1dGguem9vbS51cyIsInVpZCI6IjRRVGdySkJnUUkyNWktQlNyUlBMS2ciLCJuYmYiOjE3MTMyMDY1NTEsImV4cCI6MTcxMzIxMDE1MSwiaWF0IjoxNzEzMjA2NTUxLCJhaWQiOiJyakZvWFF5R1RuR2tyNnJXdVhaZWJ3In0.6kCw43-dq6Vy4t3-GYcbB2oQkr8iQDrgX9TmRgVR-4tzmD04CPIgX62rMaqgc44S9fJkF77LMX6C4oLd-U_ssw', 'token_type': 'bearer', 'refresh_token': 'eyJzdiI6IjAwMDAwMSIsImFsZyI6IkhTNTEyIiwidiI6IjIuMCIsImtpZCI6IjQ0MGNmNmM4LTgwOGQtNGQwMC05MDk2LTkwNjdmODBhZDM1NyJ9.eyJ2ZXIiOjksImF1aWQiOiI2NmQ1MzMxODA5NzZhNjQ5MGY5YzQzODdlNjc2YTQxNSIsImNvZGUiOiJSc1ZqS3ZoZTNpbGI5VXptOWFGU1N1NWNXYnBYVjhPZXciLCJpc3MiOiJ6bTpjaWQ6UWhoWmZIYXdSbE4xdEtqNkJ2S1BBIiwiZ25vIjowLCJ0eXBlIjoxLCJ0aWQiOjAsImF1ZCI6Imh0dHBzOi8vb2F1dGguem9vbS51cyIsInVpZCI6IjRRVGdySkJnUUkyNWktQlNyUlBMS2ciLCJuYmYiOjE3MTMyMDY1NTEsImV4cCI6MTcyMDk4MjU1MSwiaWF0IjoxNzEzMjA2NTUxLCJhaWQiOiJyakZvWFF5R1RuR2tyNnJXdVhaZWJ3In0.sEUcZbTfMEpEuPm9uZrsC-X3CwmqgzMxg7IDQMpAdM5npGCUvVFpTraznf60NQ-DMYGNg3jPqYLsptCnYBGD4w', 'expires_in': 3599, 'scope': 'meeting:read'}
ERROR:zoomOAUTH:Exception on /getAccess [GET]
Traceback (most recent call last):
  File "/home/austinmedina/DataLabMetrtics/Metrics/lib/python3.10/site-packages/flask/app.py", line 1463, in wsgi_app
    response = self.full_dispatch_request()
  File "/home/austinmedina/DataLabMetrtics/Metrics/lib/python3.10/site-packages/flask/app.py", line 872, in full_dispatch_request
    rv = self.handle_user_exception(e)
  File "/home/austinmedina/DataLabMetrtics/Metrics/lib/python3.10/site-packages/flask/app.py", line 870, in full_dispatch_request
    rv = self.dispatch_request()
  File "/home/austinmedina/DataLabMetrtics/Metrics/lib/python3.10/site-packages/flask/app.py", line 855, in dispatch_request
    return self.ensure_sync(self.view_functions[rule.endpoint])(**view_args)  # type: ignore[no-any-return]
  File "/home/austinmedina/DataLabMetrtics/zoomApp/zoomOAUTH.py", line 55, in getAccess
    session['refresh_token'] = re['refresh_token']
  File "/home/austinmedina/DataLabMetrtics/Metrics/lib/python3.10/site-packages/flask/sessions.py", line 102, in _fail
    raise RuntimeError(
RuntimeError: The session is unavailable because no secret key was set.  Set the secret_key on the application to something unique and secret.
INFO:werkzeug:127.0.0.1 - - [15/Apr/2024 11:42:31] "[35m[1mGET /getAccess?code=RsVjKvhe3ilb9Uzm9aFSSu5cWbpXV8Oew HTTP/1.1[0m" 500 -
DEBUG:urllib3.connectionpool:Starting new HTTPS connection (1): zoom.us:443
DEBUG:urllib3.connectionpool:https://zoom.us:443 "POST /oauth/token HTTP/1.1" 200 None
INFO:zoomOAUTH:{'access_token': 'eyJzdiI6IjAwMDAwMSIsImFsZyI6IkhTNTEyIiwidiI6IjIuMCIsImtpZCI6ImZmY2U0ZGQyLWI4NGEtNGZhMC05NGU4LWFjZmVjNDU0MzVjYiJ9.eyJ2ZXIiOjksImF1aWQiOiI2NmQ1MzMxODA5NzZhNjQ5MGY5YzQzODdlNjc2YTQxNSIsImNvZGUiOiJrRXJseXNrTENSMlhoeTBlZ0kxUjRtZGZkaHpKRWtVZUEiLCJpc3MiOiJ6bTpjaWQ6UWhoWmZIYXdSbE4xdEtqNkJ2S1BBIiwiZ25vIjowLCJ0eXBlIjowLCJ0aWQiOjAsImF1ZCI6Imh0dHBzOi8vb2F1dGguem9vbS51cyIsInVpZCI6IjRRVGdySkJnUUkyNWktQlNyUlBMS2ciLCJuYmYiOjE3MTMyMDY2MDEsImV4cCI6MTcxMzIxMDIwMSwiaWF0IjoxNzEzMjA2NjAxLCJhaWQiOiJyakZvWFF5R1RuR2tyNnJXdVhaZWJ3In0.rqeSiKsVm4yxl9RM2L6HHRN-8RUu3glhKN__o40OmcMoMHPpsLkx8Zx8NLUzWCRro3kEUVxjOz03Nn4oBb4CRw', 'token_type': 'bearer', 'refresh_token': 'eyJzdiI6IjAwMDAwMSIsImFsZyI6IkhTNTEyIiwidiI6IjIuMCIsImtpZCI6IjUyOTU3MzhkLTNlMTktNDQ3My05NjA2LTJkYWQzYjZiNDA1NCJ9.eyJ2ZXIiOjksImF1aWQiOiI2NmQ1MzMxODA5NzZhNjQ5MGY5YzQzODdlNjc2YTQxNSIsImNvZGUiOiJrRXJseXNrTENSMlhoeTBlZ0kxUjRtZGZkaHpKRWtVZUEiLCJpc3MiOiJ6bTpjaWQ6UWhoWmZIYXdSbE4xdEtqNkJ2S1BBIiwiZ25vIjowLCJ0eXBlIjoxLCJ0aWQiOjAsImF1ZCI6Imh0dHBzOi8vb2F1dGguem9vbS51cyIsInVpZCI6IjRRVGdySkJnUUkyNWktQlNyUlBMS2ciLCJuYmYiOjE3MTMyMDY2MDEsImV4cCI6MTcyMDk4MjYwMSwiaWF0IjoxNzEzMjA2NjAxLCJhaWQiOiJyakZvWFF5R1RuR2tyNnJXdVhaZWJ3In0.cQGceaPGNokVmAsbyjTllkexV5Vgn4M414qV-UEzQ2FAdwq2vvcKUTPUP3Dsd5KKba3dEkMHDLCj8cw6uyUBzA', 'expires_in': 3599, 'scope': 'meeting:read'}
ERROR:zoomOAUTH:Exception on /getAccess [GET]
Traceback (most recent call last):
  File "/home/austinmedina/DataLabMetrtics/Metrics/lib/python3.10/site-packages/flask/app.py", line 1463, in wsgi_app
    response = self.full_dispatch_request()
  File "/home/austinmedina/DataLabMetrtics/Metrics/lib/python3.10/site-packages/flask/app.py", line 872, in full_dispatch_request
    rv = self.handle_user_exception(e)
  File "/home/austinmedina/DataLabMetrtics/Metrics/lib/python3.10/site-packages/flask/app.py", line 870, in full_dispatch_request
    rv = self.dispatch_request()
  File "/home/austinmedina/DataLabMetrtics/Metrics/lib/python3.10/site-packages/flask/app.py", line 855, in dispatch_request
    return self.ensure_sync(self.view_functions[rule.endpoint])(**view_args)  # type: ignore[no-any-return]
  File "/home/austinmedina/DataLabMetrtics/zoomApp/zoomOAUTH.py", line 55, in getAccess
    re = response.json()
  File "/home/austinmedina/DataLabMetrtics/Metrics/lib/python3.10/site-packages/flask/sessions.py", line 102, in _fail
    raise RuntimeError(
RuntimeError: The session is unavailable because no secret key was set.  Set the secret_key on the application to something unique and secret.
INFO:werkzeug:127.0.0.1 - - [15/Apr/2024 11:43:21] "[35m[1mGET /getAccess?code=kErlyskLCR2Xhy0egI1R4mdfdhzJEkUeA HTTP/1.1[0m" 500 -
INFO:werkzeug:[31m[1mWARNING: This is a development server. Do not use it in a production deployment. Use a production WSGI server instead.[0m
 * Running on http://127.0.0.1:5000
INFO:werkzeug:[33mPress CTRL+C to quit[0m
DEBUG:urllib3.connectionpool:Starting new HTTPS connection (1): zoom.us:443
DEBUG:urllib3.connectionpool:https://zoom.us:443 "POST /oauth/token HTTP/1.1" 200 None
INFO:zoomOAUTH:{'access_token': 'eyJzdiI6IjAwMDAwMSIsImFsZyI6IkhTNTEyIiwidiI6IjIuMCIsImtpZCI6ImE1OWM1NzEwLTRkNjItNDgxMy1iYjY0LTA3NDYzOGI4Njg1MyJ9.eyJ2ZXIiOjksImF1aWQiOiI2NmQ1MzMxODA5NzZhNjQ5MGY5YzQzODdlNjc2YTQxNSIsImNvZGUiOiI2Tk9LRDFYanlHcnltQmprbzlKVG4yXzZPWGw4T3BtVWciLCJpc3MiOiJ6bTpjaWQ6UWhoWmZIYXdSbE4xdEtqNkJ2S1BBIiwiZ25vIjowLCJ0eXBlIjowLCJ0aWQiOjAsImF1ZCI6Imh0dHBzOi8vb2F1dGguem9vbS51cyIsInVpZCI6IjRRVGdySkJnUUkyNWktQlNyUlBMS2ciLCJuYmYiOjE3MTMyMDY2MTAsImV4cCI6MTcxMzIxMDIxMCwiaWF0IjoxNzEzMjA2NjEwLCJhaWQiOiJyakZvWFF5R1RuR2tyNnJXdVhaZWJ3In0.-xzy8WdIP5P25jzQu06PQasIy7hiFZB2OmYzqDkDD9V0wPoVsm3ASVH54P2MYSJLttDNVG0XrtiD_U9Nm4a1mg', 'token_type': 'bearer', 'refresh_token': 'eyJzdiI6IjAwMDAwMSIsImFsZyI6IkhTNTEyIiwidiI6IjIuMCIsImtpZCI6IjE1NTQzMTNkLTkwOTYtNGIxOC1iNmI3LTUxYzYzMWRiMDEzYyJ9.eyJ2ZXIiOjksImF1aWQiOiI2NmQ1MzMxODA5NzZhNjQ5MGY5YzQzODdlNjc2YTQxNSIsImNvZGUiOiI2Tk9LRDFYanlHcnltQmprbzlKVG4yXzZPWGw4T3BtVWciLCJpc3MiOiJ6bTpjaWQ6UWhoWmZIYXdSbE4xdEtqNkJ2S1BBIiwiZ25vIjowLCJ0eXBlIjoxLCJ0aWQiOjAsImF1ZCI6Imh0dHBzOi8vb2F1dGguem9vbS51cyIsInVpZCI6IjRRVGdySkJnUUkyNWktQlNyUlBMS2ciLCJuYmYiOjE3MTMyMDY2MTAsImV4cCI6MTcyMDk4MjYxMCwiaWF0IjoxNzEzMjA2NjEwLCJhaWQiOiJyakZvWFF5R1RuR2tyNnJXdVhaZWJ3In0.lDWdgGYTg25AcYzxNpzuQDe5ja25p52Kefk_IsIWOd_m3tCZhrJ2sWMsO7TPdmFMpaXkrrayCEFv_TZMsih4sA', 'expires_in': 3599, 'scope': 'meeting:read'}
INFO:werkzeug:127.0.0.1 - - [15/Apr/2024 11:43:30] "[32mGET /getAccess?code=6NOKD1XjyGrymBjko9JTn2_6OXl8OpmUg HTTP/1.1[0m" 302 -
ERROR:zoomOAUTH:Exception on /getMeetingID [GET]
Traceback (most recent call last):
  File "/home/austinmedina/DataLabMetrtics/Metrics/lib/python3.10/site-packages/flask/app.py", line 1463, in wsgi_app
    response = self.full_dispatch_request()
  File "/home/austinmedina/DataLabMetrtics/Metrics/lib/python3.10/site-packages/flask/app.py", line 872, in full_dispatch_request
    rv = self.handle_user_exception(e)
  File "/home/austinmedina/DataLabMetrtics/Metrics/lib/python3.10/site-packages/flask/app.py", line 870, in full_dispatch_request
    rv = self.dispatch_request()
  File "/home/austinmedina/DataLabMetrtics/Metrics/lib/python3.10/site-packages/flask/app.py", line 855, in dispatch_request
    return self.ensure_sync(self.view_functions[rule.endpoint])(**view_args)  # type: ignore[no-any-return]
  File "/home/austinmedina/DataLabMetrtics/zoomApp/zoomOAUTH.py", line 94, in getMeetingID
    return render_template('ZoomIDForm.html')
  File "/home/austinmedina/DataLabMetrtics/Metrics/lib/python3.10/site-packages/flask/templating.py", line 149, in render_template
    template = app.jinja_env.get_or_select_template(template_name_or_list)
  File "/home/austinmedina/DataLabMetrtics/Metrics/lib/python3.10/site-packages/jinja2/environment.py", line 1081, in get_or_select_template
    return self.get_template(template_name_or_list, parent, globals)
  File "/home/austinmedina/DataLabMetrtics/Metrics/lib/python3.10/site-packages/jinja2/environment.py", line 1010, in get_template
    return self._load_template(name, globals)
  File "/home/austinmedina/DataLabMetrtics/Metrics/lib/python3.10/site-packages/jinja2/environment.py", line 969, in _load_template
    template = self.loader.load(self, name, self.make_globals(globals))
  File "/home/austinmedina/DataLabMetrtics/Metrics/lib/python3.10/site-packages/jinja2/loaders.py", line 125, in load
    source, filename, uptodate = self.get_source(environment, name)
  File "/home/austinmedina/DataLabMetrtics/Metrics/lib/python3.10/site-packages/flask/templating.py", line 65, in get_source
    return self._get_source_fast(environment, template)
  File "/home/austinmedina/DataLabMetrtics/Metrics/lib/python3.10/site-packages/flask/templating.py", line 99, in _get_source_fast
    raise TemplateNotFound(template)
jinja2.exceptions.TemplateNotFound: ZoomIDForm.html
INFO:werkzeug:127.0.0.1 - - [15/Apr/2024 11:43:30] "[35m[1mGET /getMeetingID HTTP/1.1[0m" 500 -
INFO:werkzeug:[31m[1mWARNING: This is a development server. Do not use it in a production deployment. Use a production WSGI server instead.[0m
 * Running on http://127.0.0.1:5000
INFO:werkzeug:[33mPress CTRL+C to quit[0m
DEBUG:urllib3.connectionpool:Starting new HTTPS connection (1): zoom.us:443
DEBUG:urllib3.connectionpool:https://zoom.us:443 "POST /oauth/token HTTP/1.1" 200 None
INFO:zoomOAUTH:{'access_token': 'eyJzdiI6IjAwMDAwMSIsImFsZyI6IkhTNTEyIiwidiI6IjIuMCIsImtpZCI6ImU2OTgxYjk1LTc0NTktNGE1OS1iYTA4LTc4NWYzYWNkNmRmMiJ9.eyJ2ZXIiOjksImF1aWQiOiI2NmQ1MzMxODA5NzZhNjQ5MGY5YzQzODdlNjc2YTQxNSIsImNvZGUiOiJzcnlzcGdGY0JuSWVpeFBZUFlMUTBTb0VpSFB0bjV1LWciLCJpc3MiOiJ6bTpjaWQ6UWhoWmZIYXdSbE4xdEtqNkJ2S1BBIiwiZ25vIjowLCJ0eXBlIjowLCJ0aWQiOjAsImF1ZCI6Imh0dHBzOi8vb2F1dGguem9vbS51cyIsInVpZCI6IjRRVGdySkJnUUkyNWktQlNyUlBMS2ciLCJuYmYiOjE3MTMyMDY2NTYsImV4cCI6MTcxMzIxMDI1NiwiaWF0IjoxNzEzMjA2NjU2LCJhaWQiOiJyakZvWFF5R1RuR2tyNnJXdVhaZWJ3In0.tScrusabhjx6l0V0UIti0ylhHvhmqMoBlznVOutFUOWtuZALp4ITOaq47B3A-QZe3QEOn_v9nLetUdK_acThcg', 'token_type': 'bearer', 'refresh_token': 'eyJzdiI6IjAwMDAwMSIsImFsZyI6IkhTNTEyIiwidiI6IjIuMCIsImtpZCI6ImI5MjIwN2VjLTQxOWMtNDc5OC05ODNiLTRlZjA5N2ZjYjVjYiJ9.eyJ2ZXIiOjksImF1aWQiOiI2NmQ1MzMxODA5NzZhNjQ5MGY5YzQzODdlNjc2YTQxNSIsImNvZGUiOiJzcnlzcGdGY0JuSWVpeFBZUFlMUTBTb0VpSFB0bjV1LWciLCJpc3MiOiJ6bTpjaWQ6UWhoWmZIYXdSbE4xdEtqNkJ2S1BBIiwiZ25vIjowLCJ0eXBlIjoxLCJ0aWQiOjAsImF1ZCI6Imh0dHBzOi8vb2F1dGguem9vbS51cyIsInVpZCI6IjRRVGdySkJnUUkyNWktQlNyUlBMS2ciLCJuYmYiOjE3MTMyMDY2NTYsImV4cCI6MTcyMDk4MjY1NiwiaWF0IjoxNzEzMjA2NjU2LCJhaWQiOiJyakZvWFF5R1RuR2tyNnJXdVhaZWJ3In0.-0Ii9U9OHe-qv1c5T6guebPedSRq5JXjZKJOo4XpcHi2OXCdR2sl6cSCzf2No0D_BbFni3nwI9_NlUIhF78-2Q', 'expires_in': 3599, 'scope': 'meeting:read'}
INFO:werkzeug:127.0.0.1 - - [15/Apr/2024 11:44:16] "[32mGET /getAccess?code=sryspgFcBnIeixPYPYLQ0SoEiHPtn5u-g HTTP/1.1[0m" 302 -
INFO:werkzeug:127.0.0.1 - - [15/Apr/2024 11:44:16] "GET /getMeetingID HTTP/1.1" 200 -
INFO:werkzeug:127.0.0.1 - - [15/Apr/2024 11:44:19] "[32mPOST /getMeetingID HTTP/1.1[0m" 302 -
INFO:werkzeug:127.0.0.1 - - [15/Apr/2024 11:44:19] "GET /getMeetingID HTTP/1.1" 200 -
